Workbook

Sheet Business Brief
A1: EXCEL FUNDAMENTALS MINI PROJECT | B1: Northbridge Retail — fictional UK business
A2: Your role | B2: Junior Data Analyst
A3: Manager request | B3: Clean our sales export, assess performance, and explain what management should do next.
A4: Period | B4: January–June 2026. All names, customers and transactions are fictional.
A5: First instruction | B5: Do not analyse or clean yet. Inspect Raw Sales and report the data-quality problems you identify, with examples.
A6: Final deliverables | B6: A preserved raw export, cleaned dataset, documented cleaning decisions, analysis, PivotTables, charts and a small management dashboard.
A7: Business questions | B7: How have revenue and gross profit changed over time? Which products, categories and regions perform well? What do customer types and salespeople reveal?
A8: Business reasoning | B8: Write 3–5 findings supported by numbers and 2 practical recommendations. Explain any limitations.
A9: Independence | B9: Choose your own formulas, PivotTables and charts. Notes and previous examples are allowed. No Power Query, macros or advanced techniques are required.
A10: Financial definitions | B10: Revenue = quantity × selling price × (1 − discount rate). Product cost = quantity × unit cost. Gross profit = revenue − product cost. Gross margin = gross profit ÷ revenue.
A11: Scope | B11: Prices exclude VAT. Ignore delivery charges, tax and overheads. This project measures gross profit, not net profit.
A12: Transaction grain | B12: One row represents one order containing one product. Order ID should identify one transaction. Every record represents a completed sale.
... A15: Assessment | B15: Data cleaning, formula accuracy, PivotTables, chart choice, presentation, analysis and business reasoning. No worked answers are included.

Sheet Product Reference
A1: Product ID | B1: Product | C1: Category | D1: Standard Unit Cost
A2: P01 | B2: Laptop | C2: Computers | D2: 430
A3: P02 | B3: Monitor | C3: Computers | D3: 95
A4: P03 | B4: Tablet | C4: Computers | D4: 155
A5: P04 | B5: Keyboard | C5: Accessories | D5: 14
A6: P05 | B6: Mouse | C6: Accessories | D6: 7
A7: P06 | B7: Headphones | C7: Accessories | D7: 22
A8: P07 | B8: Desk | C8: Furniture | D8: 95
A9: P08 | B9: Office Chair | C9: Furniture | D9: 65

Sheet Customer Reference
A1: Customer ID | B1: Customer Name | C1: Customer Type
A2: C001 | B2: River Customer 01 | C2: B2C
A3: C002 | B3: Cedar Customer 02 | C3: B2C
A4: C003 | B4: Hill Customer 03 | C4: B2B
A5: C004 | B5: Park Customer 04 | C5: B2C
A6: C005 | B6: Maple Customer 05 | C6: B2C
A7: C006 | B7: Oak Customer 06 | C7: B2B
A8: C007 | B8: River Customer 07 | C8: B2C
A9: C008 | B9: Cedar Customer 08 | C9: B2C
A10: C009 | B10: Hill Customer 09 | C10: B2B
A11: C010 | B11: Park Customer 10 | C11: B2C
A12: C011 | B12: Maple Customer 11 | C12: B2C
... A41: C040 | B41: Park Customer 40 | C41: B2C

Sheet Date Analysis
A3: Row Labels | B3: Sum of Revenue | C3: Sum of Gross Profit | D3: Gross Margin
A4: Jan | B4: 36590.3 | C4: 14403.3 | D4: =GETPIVOTDATA("Sum of Gross Profit",$A$3,"Months (Order Date)",1)/GETPIVOTDATA("Sum of Revenue",$A$3,"Months (Order Date)",1) -> 0.39363711
A5: Feb | B5: 23436.825 | C5: 9771.825 | D5: =GETPIVOTDATA("Sum of Gross Profit",$A$3,"Months (Order Date)",2)/GETPIVOTDATA("Sum of Revenue",$A$3,"Months (Order Date)",2) -> 0.41694321
A6: Mar | B6: 38459.537 | C6: 13741.538 | D6: =GETPIVOTDATA("Sum of Gross Profit",$A$3,"Months (Order Date)",3)/GETPIVOTDATA("Sum of Revenue",$A$3,"Months (Order Date)",3) -> 0.35729856
A7: Apr | B7: 51197.563 | C7: 19271.562 | D7: =GETPIVOTDATA("Sum of Gross Profit",$A$3,"Months (Order Date)",4)/GETPIVOTDATA("Sum of Revenue",$A$3,"Months (Order Date)",4) -> 0.37641563
A8: May | B8: 31820.775 | C8: 13547.775 | D8: =GETPIVOTDATA("Sum of Gross Profit",$A$3,"Months (Order Date)",5)/GETPIVOTDATA("Sum of Revenue",$A$3,"Months (Order Date)",5) -> 0.42575252
A9: Jun | B9: 48999.162 | C9: 17800.163 | D9: =GETPIVOTDATA("Sum of Gross Profit",$A$3,"Months (Order Date)",6)/GETPIVOTDATA("Sum of Revenue",$A$3,"Months (Order Date)",6) -> 0.36327483
A10: Grand Total | B10: 230504.16 | C10: 88536.163

Sheet Saleperson Analysis
A3: Row Labels | B3: Sum of Revenue | C3: Sum of Gross Profit | D3: Count of Order ID | E3: Gross Margin
A4: Aisha Khan | B4: 88181.212 | C4: 32972.212 | D4: 112 | E4: =GETPIVOTDATA("Sum of Gross Profit",$A$3,"Salesperson","Aisha Khan")/GETPIVOTDATA("Sum of Revenue",$A$3,"Salesperson","Aisha Khan") -> 0.37391426
A5: Chloe Evans | B5: 59522.038 | C5: 22128.038 | D5: 90 | E5: =GETPIVOTDATA("Sum of Gross Profit",$A$3,"Salesperson","Chloe Evans")/GETPIVOTDATA("Sum of Revenue",$A$3,"Salesperson","Chloe Evans") -> 0.3717621
A6: Daniel Reed | B6: 43073.15 | C6: 17709.15 | D6: 78 | E6: =GETPIVOTDATA("Sum of Gross Profit",$A$3,"Salesperson","Daniel Reed")/GETPIVOTDATA("Sum of Revenue",$A$3,"Salesperson","Daniel Reed") -> 0.41114128
A7: Ben Clarke | B7: 38440.988 | C7: 15092.987 | D7: 76 | E7: =GETPIVOTDATA("Sum of Gross Profit",$A$3,"Salesperson","Ben Clarke")/GETPIVOTDATA("Sum of Revenue",$A$3,"Salesperson","Ben Clarke") -> 0.39262747
A8: Unknown | B8: 1286.775 | C8: 633.775 | D8: 2 | E8: =GETPIVOTDATA("Sum of Gross Profit",$A$3,"Salesperson","Unknown")/GETPIVOTDATA("Sum of Revenue",$A$3,"Salesperson","Unknown") -> 0.49252977
A9: Grand Total | B9: 230504.16 | C9: 88536.162 | D9: 358 | E9: =GETPIVOTDATA("Sum of Gross Profit",$A$3)/GETPIVOTDATA("Sum of Revenue",$A$3) -> 0.38409789

Sheet Dashboard
A1: Sales Performance Dashboard
A3: January - June 2026 . UK retail . 358 cleaned order
A5: Total Revenue | E5: Gross Profit | I5: Gross Margin | M5: Orders
A6: =SUM(Sales[Revenue]) -> 230504.16 | E6: =SUM(Sales[Gross Profit]) -> 88536.162 | I6: =E6/A6 -> 0.38409789 | M6: =COUNTA(Sales[Order ID]) -> 358

Sheet Clean Sheet
A1: Order ID | B1: Order Date | C1: Product ID | D1: Product | E1: Category | F1: Region | G1: Customer ID | H1: Customer Name | I1: Customer Type | J1: Salesperson | K1: Quantity | L1: Unit Price | M1: Unit Cost | N1: Discount Rate | O1: Revenue | P1: Product cost | Q1: Gross Profit | R1: Gross Margin
A2: NB10288 | B2: 46024 | C2: P01 | D2: Laptop | E2: Computers | F2: London | G2: C027 | H2: Hill Customer 27 | I2: B2B | J2: Aisha Khan | K2: 11 | L2: 682.5 | M2: 430 | N2: 0.05 | O2: =Sales[[#This Row],[Quantity]]*Sales[[#This Row],[Unit Price]]*(1-Sales[[#This Row],[Discount Rate]]) -> 7132.125 | P2: =Sales[[#This Row],[Unit Cost]]*Sales[[#This Row],[Quantity]] -> 4730 | Q2: =Sales[[#This Row],[Revenue]]-Sales[[#This Row],[Product cost]] -> 2402.125 | R2: =Sales[[#This Row],[Gross Profit]]/Sales[[#This Row],[Revenue]] -> 0.33680355
A3: NB10187 | B3: 46084 | C3: P01 | D3: Laptop | E3: Computers | F3: North West | G3: C021 | H3: Hill Customer 21 | I3: B2B | J3: Aisha Khan | K3: 10 | L3: 617.5 | M3: 430 | N3: 0 | O3: =Sales[[#This Row],[Quantity]]*Sales[[#This Row],[Unit Price]]*(1-Sales[[#This Row],[Discount Rate]]) -> 6175 | P3: =Sales[[#This Row],[Unit Cost]]*Sales[[#This Row],[Quantity]] -> 4300 | Q3: =Sales[[#This Row],[Revenue]]-Sales[[#This Row],[Product cost]] -> 1875 | R3: =Sales[[#This Row],[Gross Profit]]/Sales[[#This Row],[Revenue]] -> 0.30364372
A4: NB10229 | B4: 46194 | C4: P01 | D4: Laptop | E4: Computers | F4: Midlands | G4: C009 | H4: Hill Customer 09 | I4: B2B | J4: Aisha Khan | K4: 8 | L4: 650 | M4: 430 | N4: 0.05 | O4: =Sales[[#This Row],[Quantity]]*Sales[[#This Row],[Unit Price]]*(1-Sales[[#This Row],[Discount Rate]]) -> 4940 | P4: =Sales[[#This Row],[Unit Cost]]*Sales[[#This Row],[Quantity]] -> 3440 | Q4: =Sales[[#This Row],[Revenue]]-Sales[[#This Row],[Product cost]] -> 1500 | R4: =Sales[[#This Row],[Gross Profit]]/Sales[[#This Row],[Revenue]] -> 0.30364372
A5: NB10095 | B5: 46130 | C5: P01 | D5: Laptop | E5: Computers | F5: Midlands | G5: C027 | H5: Hill Customer 27 | I5: B2B | J5: Aisha Khan | K5: 7 | L5: 682.5 | M5: 430 | N5: 0 | O5: =Sales[[#This Row],[Quantity]]*Sales[[#This Row],[Unit Price]]*(1-Sales[[#This Row],[Discount Rate]]) -> 4777.5 | P5: =Sales[[#This Row],[Unit Cost]]*Sales[[#This Row],[Quantity]] -> 3010 | Q5: =Sales[[#This Row],[Revenue]]-Sales[[#This Row],[Product cost]] -> 1767.5 | R5: =Sales[[#This Row],[Gross Profit]]/Sales[[#This Row],[Revenue]] -> 0.36996337
A6: NB10008 | B6: 46182 | C6: P01 | D6: Laptop | E6: Computers | F6: South East | G6: C036 | H6: Oak Customer 36 | I6: B2B | J6: Chloe Evans | K6: 7 | L6: 650 | M6: 430 | N6: 0.05 | O6: =Sales[[#This Row],[Quantity]]*Sales[[#This Row],[Unit Price]]*(1-Sales[[#This Row],[Discount Rate]]) -> 4322.5 | P6: =Sales[[#This Row],[Unit Cost]]*Sales[[#This Row],[Quantity]] -> 3010 | Q6: =Sales[[#This Row],[Revenue]]-Sales[[#This Row],[Product cost]] -> 1312.5 | R6: =Sales[[#This Row],[Gross Profit]]/Sales[[#This Row],[Revenue]] -> 0.30364372
A7: NB10356 | B7: 46115 | C7: P01 | D7: Laptop | E7: Computers | F7: North West | G7: C024 | H7: Oak Customer 24 | I7: B2B | J7: Aisha Khan | K7: 7 | L7: 617.5 | M7: 430 | N7: 0.05 | O7: =Sales[[#This Row],[Quantity]]*Sales[[#This Row],[Unit Price]]*(1-Sales[[#This Row],[Discount Rate]]) -> 4106.375 | P7: =Sales[[#This Row],[Unit Cost]]*Sales[[#This Row],[Quantity]] -> 3010 | Q7: =Sales[[#This Row],[Revenue]]-Sales[[#This Row],[Product cost]] -> 1096.375 | R7: =Sales[[#This Row],[Gross Profit]]/Sales[[#This Row],[Revenue]] -> 0.26699339
A8: NB10168 | B8: 46137 | C8: P03 | D8: Tablet | E8: Computers | F8: Midlands | G8: C024 | H8: Oak Customer 24 | I8: B2B | J8: Chloe Evans | K8: 12 | L8: 273 | M8: 155 | N8: 0 | O8: =Sales[[#This Row],[Quantity]]*Sales[[#This Row],[Unit Price]]*(1-Sales[[#This Row],[Discount Rate]]) -> 3276 | P8: =Sales[[#This Row],[Unit Cost]]*Sales[[#This Row],[Quantity]] -> 1860 | Q8: =Sales[[#This Row],[Revenue]]-Sales[[#This Row],[Product cost]] -> 1416 | R8: =Sales[[#This Row],[Gross Profit]]/Sales[[#This Row],[Revenue]] -> 0.43223443
A9: NB10326 | B9: 46118 | C9: P01 | D9: Laptop | E9: Computers | F9: London | G9: C039 | H9: Hill Customer 39 | I9: B2B | J9: Aisha Khan | K9: 5 | L9: 682.5 | M9: 430 | N9: 0.15 | O9: =Sales[[#This Row],[Quantity]]*Sales[[#This Row],[Unit Price]]*(1-Sales[[#This Row],[Discount Rate]]) -> 2900.625 | P9: =Sales[[#This Row],[Unit Cost]]*Sales[[#This Row],[Quantity]] -> 2150 | Q9: =Sales[[#This Row],[Revenue]]-Sales[[#This Row],[Product cost]] -> 750.625 | R9: =Sales[[#This Row],[Gross Profit]]/Sales[[#This Row],[Revenue]] -> 0.25878044
A10: NB10045 | B10: 46100 | C10: P01 | D10: Laptop | E10: Computers | F10: North West | G10: C020 | H10: Cedar Customer 20 | I10: B2C | J10: Aisha Khan | K10: 4 | L10: 650 | M10: 430 | N10: 0 | O10: =Sales[[#This Row],[Quantity]]*Sales[[#This Row],[Unit Price]]*(1-Sales[[#This Row],[Discount Rate]]) -> 2600 | P10: =Sales[[#This Row],[Unit Cost]]*Sales[[#This Row],[Quantity]] -> 1720 | Q10: =Sales[[#This Row],[Revenue]]-Sales[[#This Row],[Product cost]] -> 880 | R10: =Sales[[#This Row],[Gross Profit]]/Sales[[#This Row],[Revenue]] -> 0.33846154
A11: NB10292 | B11: 46150 | C11: P01 | D11: Laptop | E11: Computers | F11: London | G11: C025 | H11: River Customer 25 | I11: B2C | J11: Daniel Reed | K11: 4 | L11: 650 | M11: 430 | N11: 0 | O11: =Sales[[#This Row],[Quantity]]*Sales[[#This Row],[Unit Price]]*(1-Sales[[#This Row],[Discount Rate]]) -> 2600 | P11: =Sales[[#This Row],[Unit Cost]]*Sales[[#This Row],[Quantity]] -> 1720 | Q11: =Sales[[#This Row],[Revenue]]-Sales[[#This Row],[Product cost]] -> 880 | R11: =Sales[[#This Row],[Gross Profit]]/Sales[[#This Row],[Revenue]] -> 0.33846154
A12: NB10328 | B12: 46186 | C12: P01 | D12: Laptop | E12: Computers | F12: South East | G12: C026 | H12: Cedar Customer 26 | I12: B2C | J12: Chloe Evans | K12: 4 | L12: 650 | M12: 430 | N12: 0 | O12: =Sales[[#This Row],[Quantity]]*Sales[[#This Row],[Unit Price]]*(1-Sales[[#This Row],[Discount Rate]]) -> 2600 | P12: =Sales[[#This Row],[Unit Cost]]*Sales[[#This Row],[Quantity]] -> 1720 | Q12: =Sales[[#This Row],[Revenue]]-Sales[[#This Row],[Product cost]] -> 880 | R12: =Sales[[#This Row],[Gross Profit]]/Sales[[#This Row],[Revenue]] -> 0.33846154
A13: NB10218 | B13: 46197 | C13: P01 | D13: Laptop | E13: Computers | F13: North West | G13: C037 | H13: River Customer 37 | I13: B2C | J13: Chloe Evans | K13: 4 | L13: 650 | M13: 430 | N13: 0.05 | O13: =Sales[[#This Row],[Quantity]]*Sales[[#This Row],[Unit Price]]*(1-Sales[[#This Row],[Discount Rate]]) -> 2470 | P13: =Sales[[#This Row],[Unit Cost]]*Sales[[#This Row],[Quantity]] -> 1720 | Q13: =Sales[[#This Row],[Revenue]]-Sales[[#This Row],[Product cost]] -> 750 | R13: =Sales[[#This Row],[Gross Profit]]/Sales[[#This Row],[Revenue]] -> 0.30364372
... A21: NB10172 | B21: 46157 | C21: P07 | D21: Desk | E21: Furniture | F21: North West | G21: C003 | H21: Hill Customer 03 | I21: B2B | J21: Daniel Reed | K21: 12 | L21: 170 | M21: 95 | N21: 0 | O21: =Sales[[#This Row],[Quantity]]*Sales[[#This Row],[Unit Price]]*(1-Sales[[#This Row],[Discount Rate]]) -> 2040 | P21: =Sales[[#This Row],[Unit Cost]]*Sales[[#This Row],[Quantity]] -> 1140 | Q21: =Sales[[#This Row],[Revenue]]-Sales[[#This Row],[Product cost]] -> 900 | R21: =Sales[[#This Row],[Gross Profit]]/Sales[[#This Row],[Revenue]] -> 0.44117647
A22: NB10119 | B22: 46124 | C22: P01 | D22: Laptop | E22: Computers | F22: South East | G22: C019 | H22: River Customer 19 | I22: B2C | J22: Daniel Reed | K22: 3 | L22: 650 | M22: =_xlfn.XLOOKUP(C22, 'Product Reference'!$A$2:$A$9, 'Product Reference'!$D$2:$D$9, "Not Found") -> 430 | N22: 0 | O22: =Sales[[#This Row],[Quantity]]*Sales[[#This Row],[Unit Price]]*(1-Sales[[#This Row],[Discount Rate]]) -> 1950 | P22: =Sales[[#This Row],[Unit Cost]]*Sales[[#This Row],[Quantity]] -> 1290 | Q22: =Sales[[#This Row],[Revenue]]-Sales[[#This Row],[Product cost]] -> 660 | R22: =Sales[[#This Row],[Gross Profit]]/Sales[[#This Row],[Revenue]] -> 0.33846154
A23: NB10155 | B23: 46112 | C23: P01 | D23: Laptop | E23: Computers | F23: Midlands | G23: C034 | H23: Park Customer 34 | I23: B2C | J23: Daniel Reed | K23: 3 | L23: 650 | M23: 430 | N23: 0 | O23: =Sales[[#This Row],[Quantity]]*Sales[[#This Row],[Unit Price]]*(1-Sales[[#This Row],[Discount Rate]]) -> 1950 | P23: =Sales[[#This Row],[Unit Cost]]*Sales[[#This Row],[Quantity]] -> 1290 | Q23: =Sales[[#This Row],[Revenue]]-Sales[[#This Row],[Product cost]] -> 660 | R23: =Sales[[#This Row],[Gross Profit]]/Sales[[#This Row],[Revenue]] -> 0.33846154
A24: NB10246 | B24: 46086 | C24: P01 | D24: Laptop | E24: Computers | F24: Midlands | G24: C034 | H24: Park Customer 34 | I24: B2C | J24: Chloe Evans | K24: 3 | L24: 650 | M24: 430 | N24: 0 | O24: =Sales[[#This Row],[Quantity]]*Sales[[#This Row],[Unit Price]]*(1-Sales[[#This Row],[Discount Rate]]) -> 1950 | P24: =Sales[[#This Row],[Unit Cost]]*Sales[[#This Row],[Quantity]] -> 1290 | Q24: =Sales[[#This Row],[Revenue]]-Sales[[#This Row],[Product cost]] -> 660 | R24: =Sales[[#This Row],[Gross Profit]]/Sales[[#This Row],[Revenue]] -> 0.33846154
A25: NB10305 | B25: 46134 | C25: P01 | D25: Laptop | E25: Computers | F25: Midlands | G25: C037 | H25: River Customer 37 | I25: B2C | J25: Chloe Evans | K25: 3 | L25: 650 | M25: 430 | N25: 0 | O25: =Sales[[#This Row],[Quantity]]*Sales[[#This Row],[Unit Price]]*(1-Sales[[#This Row],[Discount Rate]]) -> 1950 | P25: =Sales[[#This Row],[Unit Cost]]*Sales[[#This Row],[Quantity]] -> 1290 | Q25: =Sales[[#This Row],[Revenue]]-Sales[[#This Row],[Product cost]] -> 660 | R25: =Sales[[#This Row],[Gross Profit]]/Sales[[#This Row],[Revenue]] -> 0.33846154
A26: NB10028 | B26: 46128 | C26: P01 | D26: Laptop | E26: Computers | F26: London | G26: C013 | H26: River Customer 13 | I26: B2C | J26: Ben Clarke | K26: 3 | L26: 682.5 | M26: 430 | N26: 0.05 | O26: =Sales[[#This Row],[Quantity]]*Sales[[#This Row],[Unit Price]]*(1-Sales[[#This Row],[Discount Rate]]) -> 1945.125 | P26: =Sales[[#This Row],[Unit Cost]]*Sales[[#This Row],[Quantity]] -> 1290 | Q26: =Sales[[#This Row],[Revenue]]-Sales[[#This Row],[Product cost]] -> 655.125 | R26: =Sales[[#This Row],[Gross Profit]]/Sales[[#This Row],[Revenue]] -> 0.33680355
A27: NB10180 | B27: 46162 | C27: P01 | D27: Laptop | E27: Computers | F27: London | G27: C039 | H27: Hill Customer 39 | I27: B2B | J27: Ben Clarke | K27: 3 | L27: 682.5 | M27: 430 | N27: 0.05 | O27: =Sales[[#This Row],[Quantity]]*Sales[[#This Row],[Unit Price]]*(1-Sales[[#This Row],[Discount Rate]]) -> 1945.125 | P27: =Sales[[#This Row],[Unit Cost]]*Sales[[#This Row],[Quantity]] -> 1290 | Q27: =Sales[[#This Row],[Revenue]]-Sales[[#This Row],[Product cost]] -> 655.125 | R27: =Sales[[#This Row],[Gross Profit]]/Sales[[#This Row],[Revenue]] -> 0.33680355
A28: NB10044 | B28: 46179 | C28: P07 | D28: Desk | E28: Furniture | F28: North West | G28: C006 | H28: Oak Customer 06 | I28: B2B | J28: Daniel Reed | K28: 11 | L28: 170 | M28: 95 | N28: 0 | O28: =Sales[[#This Row],[Quantity]]*Sales[[#This Row],[Unit Price]]*(1-Sales[[#This Row],[Discount Rate]]) -> 1870 | P28: =Sales[[#This Row],[Unit Cost]]*Sales[[#This Row],[Quantity]] -> 1045 | Q28: =Sales[[#This Row],[Revenue]]-Sales[[#This Row],[Product cost]] -> 825 | R28: =Sales[[#This Row],[Gross Profit]]/Sales[[#This Row],[Revenue]] -> 0.44117647
A29: NB10197 | B29: 46036 | C29: P07 | D29: Desk | E29: Furniture | F29: South East | G29: C021 | H29: Hill Customer 21 | I29: B2B | J29: Aisha Khan | K29: 11 | L29: 170 | M29: 95 | N29: 0 | O29: =Sales[[#This Row],[Quantity]]*Sales[[#This Row],[Unit Price]]*(1-Sales[[#This Row],[Discount Rate]]) -> 1870 | P29: =Sales[[#This Row],[Unit Cost]]*Sales[[#This Row],[Quantity]] -> 1045 | Q29: =Sales[[#This Row],[Revenue]]-Sales[[#This Row],[Product cost]] -> 825 | R29: =Sales[[#This Row],[Gross Profit]]/Sales[[#This Row],[Revenue]] -> 0.44117647
A30: NB10048 | B30: 46149 | C30: P03 | D30: Tablet | E30: Computers | F30: London | G30: C006 | H30: Oak Customer 06 | I30: B2B | J30: Aisha Khan | K30: 7 | L30: 260 | M30: 155 | N30: 0 | O30: =Sales[[#This Row],[Quantity]]*Sales[[#This Row],[Unit Price]]*(1-Sales[[#This Row],[Discount Rate]]) -> 1820 | P30: =Sales[[#This Row],[Unit Cost]]*Sales[[#This Row],[Quantity]] -> 1085 | Q30: =Sales[[#This Row],[Revenue]]-Sales[[#This Row],[Product cost]] -> 735 | R30: =Sales[[#This Row],[Gross Profit]]/Sales[[#This Row],[Revenue]] -> 0.40384615
A31: NB10301 | B31: 46024 | C31: P07 | D31: Desk | E31: Furniture | F31: South East | G31: C006 | H31: Oak Customer 06 | I31: B2B | J31: Chloe Evans | K31: 11 | L31: 170 | M31: 95 | N31: 0.05 | O31: =Sales[[#This Row],[Quantity]]*Sales[[#This Row],[Unit Price]]*(1-Sales[[#This Row],[Discount Rate]]) -> 1776.5 | P31: =Sales[[#This Row],[Unit Cost]]*Sales[[#This Row],[Quantity]] -> 1045 | Q31: =Sales[[#This Row],[Revenue]]-Sales[[#This Row],[Product cost]] -> 731.5 | R31: =Sales[[#This Row],[Gross Profit]]/Sales[[#This Row],[Revenue]] -> 0.41176471
A32: NB10127 | B32: 46139 | C32: P03 | D32: Tablet | E32: Computers | F32: Midlands | G32: C027 | H32: Hill Customer 27 | I32: B2B | J32: Chloe Evans | K32: 8 | L32: 260 | M32: 155 | N32: 0.15 | O32: =Sales[[#This Row],[Quantity]]*Sales[[#This Row],[Unit Price]]*(1-Sales[[#This Row],[Discount Rate]]) -> 1768 | P32: =Sales[[#This Row],[Unit Cost]]*Sales[[#This Row],[Quantity]] -> 1240 | Q32: =Sales[[#This Row],[Revenue]]-Sales[[#This Row],[Product cost]] -> 528 | R32: =Sales[[#This Row],[Gross Profit]]/Sales[[#This Row],[Revenue]] -> 0.29864253
A33: NB10261 | B33: 46105 | C33: P01 | D33: Laptop | E33: Computers | F33: Midlands | G33: C029 | H33: Maple Customer 29 | I33: B2C | J33: Aisha Khan | K33: 3 | L33: 682.5 | M33: 430 | N33: 0.15 | O33: =Sales[[#This Row],[Quantity]]*Sales[[#This Row],[Unit Price]]*(1-Sales[[#This Row],[Discount Rate]]) -> 1740.375 | P33: =Sales[[#This Row],[Unit Cost]]*Sales[[#This Row],[Quantity]] -> 1290 | Q33: =Sales[[#This Row],[Revenue]]-Sales[[#This Row],[Product cost]] -> 450.375 | R33: =Sales[[#This Row],[Gross Profit]]/Sales[[#This Row],[Revenue]] -> 0.25878044
A34: NB10036 | B34: 46197 | C34: P03 | D34: Tablet | E34: Computers | F34: North West | G34: C036 | H34: Oak Customer 36 | I34: B2B | J34: Aisha Khan | K34: 7 | L34: 247 | M34: 155 | N34: 0 | O34: =Sales[[#This Row],[Quantity]]*Sales[[#This Row],[Unit Price]]*(1-Sales[[#This Row],[Discount Rate]]) -> 1729 | P34: =Sales[[#This Row],[Unit Cost]]*Sales[[#This Row],[Quantity]] -> 1085 | Q34: =Sales[[#This Row],[Revenue]]-Sales[[#This Row],[Product cost]] -> 644 | R34: =Sales[[#This Row],[Gross Profit]]/Sales[[#This Row],[Revenue]] -> 0.37246964
... A145: NB10304 | B145: 46197 | C145: P08 | D145: Office Chair | E145: Furniture | F145: South East | G145: C009 | H145: Hill Customer 09 | I145: B2B | J145: Ben Clarke | K145: 4 | L145: 130 | M145: 65 | N145: 0.05 | O145: =Sales[[#This Row],[Quantity]]*Sales[[#This Row],[Unit Price]]*(1-Sales[[#This Row],[Discount Rate]]) -> 494 | P145: =Sales[[#This Row],[Unit Cost]]*Sales[[#This Row],[Quantity]] -> 260 | Q145: =Sales[[#This Row],[Revenue]]-Sales[[#This Row],[Product cost]] -> 234 | R145: =Sales[[#This Row],[Gross Profit]]/Sales[[#This Row],[Revenue]] -> 0.47368421
A146: NB10320 | B146: 46078 | C146: P08 | D146: Office Chair | E146: Furniture | F146: North West | G146: C016 | H146: Park Customer 16 | I146: B2C | J146: Chloe Evans | K146: 4 | L146: 123.5 | M146: =_xlfn.XLOOKUP(C146, 'Product Reference'!$A$2:$A$9, 'Product Reference'!$D$2:$D$9, "Not Found") -> 65 | N146: 0 | O146: =Sales[[#This Row],[Quantity]]*Sales[[#This Row],[Unit Price]]*(1-Sales[[#This Row],[Discount Rate]]) -> 494 | P146: =Sales[[#This Row],[Unit Cost]]*Sales[[#This Row],[Quantity]] -> 260 | Q146: =Sales[[#This Row],[Revenue]]-Sales[[#This Row],[Product cost]] -> 234 | R146: =Sales[[#This Row],[Gross Profit]]/Sales[[#This Row],[Revenue]] -> 0.47368421
A147: NB10130 | B147: 46106 | C147: P03 | D147: Tablet | E147: Computers | F147: London | G147: C004 | H147: Park Customer 04 | I147: B2C | J147: Aisha Khan | K147: 2 | L147: 273 | M147: 155 | N147: 0.1 | O147: =Sales[[#This Row],[Quantity]]*Sales[[#This Row],[Unit Price]]*(1-Sales[[#This Row],[Discount Rate]]) -> 491.4 | P147: =Sales[[#This Row],[Unit Cost]]*Sales[[#This Row],[Quantity]] -> 310 | Q147: =Sales[[#This Row],[Revenue]]-Sales[[#This Row],[Product cost]] -> 181.4 | R147: =Sales[[#This Row],[Gross Profit]]/Sales[[#This Row],[Revenue]] -> 0.36914937
A148: NB10325 | B148: 46089 | C148: P03 | D148: Tablet | E148: Computers | F148: South East | G148: C028 | H148: Park Customer 28 | I148: B2C | J148: Daniel Reed | K148: 2 | L148: 273 | M148: 155 | N148: 0.1 | O148: =Sales[[#This Row],[Quantity]]*Sales[[#This Row],[Unit Price]]*(1-Sales[[#This Row],[Discount Rate]]) -> 491.4 | P148: =Sales[[#This Row],[Unit Cost]]*Sales[[#This Row],[Quantity]] -> 310 | Q148: =Sales[[#This Row],[Revenue]]-Sales[[#This Row],[Product cost]] -> 181.4 | R148: =Sales[[#This Row],[Gross Profit]]/Sales[[#This Row],[Revenue]] -> 0.36914937
A149: NB10010 | B149: 46125 | C149: P02 | D149: Monitor | E149: Computers | F149: North West | G149: C023 | H149: Maple Customer 23 | I149: B2C | J149: Aisha Khan | K149: 3 | L149: 171 | M149: 95 | N149: 0.05 | O149: =Sales[[#This Row],[Quantity]]*Sales[[#This Row],[Unit Price]]*(1-Sales[[#This Row],[Discount Rate]]) -> 487.35 | P149: =Sales[[#This Row],[Unit Cost]]*Sales[[#This Row],[Quantity]] -> 285 | Q149: =Sales[[#This Row],[Revenue]]-Sales[[#This Row],[Product cost]] -> 202.35 | R149: =Sales[[#This Row],[Gross Profit]]/Sales[[#This Row],[Revenue]] -> 0.41520468
A150: NB10041 | B150: 46199 | C150: P02 | D150: Monitor | E150: Computers | F150: South East | G150: C013 | H150: River Customer 13 | I150: B2C | J150: Aisha Khan | K150: 3 | L150: 171 | M150: 95 | N150: 0.05 | O150: =Sales[[#This Row],[Quantity]]*Sales[[#This Row],[Unit Price]]*(1-Sales[[#This Row],[Discount Rate]]) -> 487.35 | P150: =Sales[[#This Row],[Unit Cost]]*Sales[[#This Row],[Quantity]] -> 285 | Q150: =Sales[[#This Row],[Revenue]]-Sales[[#This Row],[Product cost]] -> 202.35 | R150: =Sales[[#This Row],[Gross Profit]]/Sales[[#This Row],[Revenue]] -> 0.41520468
A151: NB10220 | B151: 46140 | C151: P03 | D151: Tablet | E151: Computers | F151: North West | G151: C014 | H151: Cedar Customer 14 | I151: B2C | J151: Daniel Reed | K151: 2 | L151: 260 | M151: 155 | N151: 0.1 | O151: =Sales[[#This Row],[Quantity]]*Sales[[#This Row],[Unit Price]]*(1-Sales[[#This Row],[Discount Rate]]) -> 468 | P151: =Sales[[#This Row],[Unit Cost]]*Sales[[#This Row],[Quantity]] -> 310 | Q151: =Sales[[#This Row],[Revenue]]-Sales[[#This Row],[Product cost]] -> 158 | R151: =Sales[[#This Row],[Gross Profit]]/Sales[[#This Row],[Revenue]] -> 0.33760684
A152: NB10271 | B152: 46126 | C152: P08 | D152: Office Chair | E152: Furniture | F152: South East | G152: C023 | H152: Maple Customer 23 | I152: B2C | J152: Aisha Khan | K152: 4 | L152: 130 | M152: 65 | N152: 0.1 | O152: =Sales[[#This Row],[Quantity]]*Sales[[#This Row],[Unit Price]]*(1-Sales[[#This Row],[Discount Rate]]) -> 468 | P152: =Sales[[#This Row],[Unit Cost]]*Sales[[#This Row],[Quantity]] -> 260 | Q152: =Sales[[#This Row],[Revenue]]-Sales[[#This Row],[Product cost]] -> 208 | R152: =Sales[[#This Row],[Gross Profit]]/Sales[[#This Row],[Revenue]] -> 0.44444444
A153: NB10232 | B153: 46129 | C153: P06 | D153: Headphones | E153: Accessories | F153: South East | G153: C009 | H153: Hill Customer 09 | I153: B2B | J153: Unknown | K153: 9 | L153: 57.75 | M153: 22 | N153: 0.1 | O153: =Sales[[#This Row],[Quantity]]*Sales[[#This Row],[Unit Price]]*(1-Sales[[#This Row],[Discount Rate]]) -> 467.775 | P153: =Sales[[#This Row],[Unit Cost]]*Sales[[#This Row],[Quantity]] -> 198 | Q153: =Sales[[#This Row],[Revenue]]-Sales[[#This Row],[Product cost]] -> 269.775 | R153: =Sales[[#This Row],[Gross Profit]]/Sales[[#This Row],[Revenue]] -> 0.57671958
A154: NB10106 | B154: 46160 | C154: P03 | D154: Tablet | E154: Computers | F154: London | G154: C029 | H154: Maple Customer 29 | I154: B2C | J154: Aisha Khan | K154: 2 | L154: 273 | M154: 155 | N154: 0.15 | O154: =Sales[[#This Row],[Quantity]]*Sales[[#This Row],[Unit Price]]*(1-Sales[[#This Row],[Discount Rate]]) -> 464.1 | P154: =Sales[[#This Row],[Unit Cost]]*Sales[[#This Row],[Quantity]] -> 310 | Q154: =Sales[[#This Row],[Revenue]]-Sales[[#This Row],[Product cost]] -> 154.1 | R154: =Sales[[#This Row],[Gross Profit]]/Sales[[#This Row],[Revenue]] -> 0.33204051
A155: NB10057 | B155: 46030 | C155: P07 | D155: Desk | E155: Furniture | F155: London | G155: C037 | H155: River Customer 37 | I155: B2C | J155: Chloe Evans | K155: 3 | L155: 170 | M155: 95 | N155: 0.1 | O155: =Sales[[#This Row],[Quantity]]*Sales[[#This Row],[Unit Price]]*(1-Sales[[#This Row],[Discount Rate]]) -> 459 | P155: =Sales[[#This Row],[Unit Cost]]*Sales[[#This Row],[Quantity]] -> 285 | Q155: =Sales[[#This Row],[Revenue]]-Sales[[#This Row],[Product cost]] -> 174 | R155: =Sales[[#This Row],[Gross Profit]]/Sales[[#This Row],[Revenue]] -> 0.37908497
A156: NB10020 | B156: 46119 | C156: P08 | D156: Office Chair | E156: Furniture | F156: North West | G156: C034 | H156: Park Customer 34 | I156: B2C | J156: Ben Clarke | K156: 4 | L156: 130 | M156: 65 | N156: 0.15 | O156: =Sales[[#This Row],[Quantity]]*Sales[[#This Row],[Unit Price]]*(1-Sales[[#This Row],[Discount Rate]]) -> 442 | P156: =Sales[[#This Row],[Unit Cost]]*Sales[[#This Row],[Quantity]] -> 260 | Q156: =Sales[[#This Row],[Revenue]]-Sales[[#This Row],[Product cost]] -> 182 | R156: =Sales[[#This Row],[Gross Profit]]/Sales[[#This Row],[Revenue]] -> 0.41176471
A157: NB10037 | B157: 46055 | C157: P03 | D157: Tablet | E157: Computers | F157: Midlands | G157: C013 | H157: River Customer 13 | I157: B2C | J157: Daniel Reed | K157: 2 | L157: 260 | M157: 155 | N157: 0.15 | O157: =Sales[[#This Row],[Quantity]]*Sales[[#This Row],[Unit Price]]*(1-Sales[[#This Row],[Discount Rate]]) -> 442 | P157: =Sales[[#This Row],[Unit Cost]]*Sales[[#This Row],[Quantity]] -> 310 | Q157: =Sales[[#This Row],[Revenue]]-Sales[[#This Row],[Product cost]] -> 132 | R157: =Sales[[#This Row],[Gross Profit]]/Sales[[#This Row],[Revenue]] -> 0.29864253
...

Sheet Customer Type Analysis
A3: Row Labels | B3: Sum of Revenue | C3: Sum of Gross Profit | D3: Gross Margin
A4: B2B | B4: 112402.22 | C4: 44723.225 | D4: =GETPIVOTDATA("Sum of Gross Profit",$A$3,"Customer Type","B2B")/GETPIVOTDATA("Sum of Revenue",$A$3,"Customer Type","B2B") -> 0.39788558
A5: B2C | B5: 118101.94 | C5: 43812.938 | D5: =GETPIVOTDATA("Sum of Gross Profit",$A$3,"Customer Type","B2C")/GETPIVOTDATA("Sum of Revenue",$A$3,"Customer Type","B2C") -> 0.3709756
A6: Grand Total | B6: 230504.16 | C6: 88536.163

Sheet Product Sheet
A3: Row Labels | B3: Sum of Revenue | C3: Sum of Gross Profit | D3: Gross Margin
A4: Laptop | B4: 99857.875 | C4: 30627.875 | D4: =GETPIVOTDATA("Sum of Gross Profit",$A$3,"Product","Laptop")/GETPIVOTDATA("Sum of Revenue",$A$3,"Product","Laptop") -> 0.30671467
A5: Tablet | B5: 37003.2 | C5: 13908.2 | D5: =GETPIVOTDATA("Sum of Gross Profit",$A$3,"Product","Tablet")/GETPIVOTDATA("Sum of Revenue",$A$3,"Product","Tablet") -> 0.37586479
A6: Desk | B6: 29512 | C6: 12032 | D6: =GETPIVOTDATA("Sum of Gross Profit",$A$3,"Product","Desk")/GETPIVOTDATA("Sum of Revenue",$A$3,"Product","Desk") -> 0.40769856
A7: Monitor | B7: 23693.85 | C7: 10773.85 | D7: =GETPIVOTDATA("Sum of Gross Profit",$A$3,"Product","Monitor")/GETPIVOTDATA("Sum of Revenue",$A$3,"Product","Monitor") -> 0.45471082
A8: Office Chair | B8: 20344.025 | C8: 9424.025 | D8: =GETPIVOTDATA("Sum of Gross Profit",$A$3,"Product","Office Chair")/GETPIVOTDATA("Sum of Revenue",$A$3,"Product","Office Chair") -> 0.46323306
A9: Headphones | B9: 9534.3875 | C9: 5530.3875 | D9: =GETPIVOTDATA("Sum of Gross Profit",$A$3,"Product","Headphones")/GETPIVOTDATA("Sum of Revenue",$A$3,"Product","Headphones") -> 0.58004644
A10: Keyboard | B10: 7349.475 | C10: 4213.475 | D10: =GETPIVOTDATA("Sum of Gross Profit",$A$3,"Product","Keyboard")/GETPIVOTDATA("Sum of Revenue",$A$3,"Product","Keyboard") -> 0.57330285
A11: Mouse | B11: 3209.35 | C11: 2026.35 | D11: =GETPIVOTDATA("Sum of Gross Profit",$A$3,"Product","Mouse")/GETPIVOTDATA("Sum of Revenue",$A$3,"Product","Mouse") -> 0.63138953
A12: Grand Total | B12: 230504.16 | C12: 88536.162
B17: =SUM(GETPIVOTDATA("Sum of Gross Profit",$A$3,"Product","Desk"), GETPIVOTDATA("Sum of Gross Profit",$A$3,"Product","Desk")) -> 24064
B20: =SUM(GETPIVOTDATA("Sum of Revenue",$A$3,"Product","Desk"),GETPIVOTDATA("Sum of Gross Profit",$A$3,"Product","Mouse")) -> 31538.35

Sheet Region Analysis
A3: Row Labels | B3: Sum of Revenue | C3: Sum of Gross Profit | D3: Gross margin
A4: North West | B4: 62029.05 | C4: 23333.05 | D4: =GETPIVOTDATA("Sum of Gross Profit",A3,"Region","North West")/GETPIVOTDATA("Sum of Revenue",A3,"Region","North West") -> 0.37616327
A5: Midlands | B5: 58851.775 | C5: 23169.775 | D5: =GETPIVOTDATA("Sum of Gross Profit",$A$3,"Region","Midlands")/GETPIVOTDATA("Sum of Revenue",$A$3,"Region","Midlands") -> 0.39369713
A6: London | B6: 58322.1 | C6: 22484.1 | D6: =GETPIVOTDATA("Sum of Gross Profit",$A$3,"Region","London")/GETPIVOTDATA("Sum of Revenue",$A$3,"Region","London") -> 0.38551595
A7: South East | B7: 51301.238 | C7: 19549.238 | D7: =GETPIVOTDATA("Sum of Gross Profit",$A$3,"Region","South East")/GETPIVOTDATA("Sum of Revenue",$A$3,"Region","South East") -> 0.38106756
A8: Grand Total | B8: 230504.16 | C8: 88536.163

Sheet Analysis Sheet
A1: Total Revenue | B1: =SUM(Sales[Revenue]) -> 230504.16
A2: Total Gross Profit | B2: =SUM(Sales[Gross Profit]) -> 88536.162
A3: Overall Gross margin | B3: =B2/B1 -> 0.38409789

Sheet Raw Sheet
A1: Order ID | B1: Order Date | C1: Product ID | D1: Product | E1: Category | F1: Region | G1: Customer ID | H1: Customer Name | I1: Customer Type | J1: Salesperson | K1: Quantity | L1: Unit Price | M1: Unit Cost | N1: Discount Rate
A2: NB10001 | B2: 46097 | C2: P08 | D2: Office Chair | E2: Furniture | F2: Midlands | G2: C027 | H2: Hill Customer 27 | I2: B2B | J2: Aisha Khan | K2: 11 | L2: 130 | M2: 65 | N2: 0
A3: NB10002 | B3: 46194 | C3: P06 | D3: Headphones | E3: Accessories | F3: North West | G3: C028 | H3: Park Customer 28 | I3: B2C | J3: Chloe Evans | K3: 1 | L3: 57.75 | M3: 22 | N3: 0
A4: NB10003 | B4: 46031 | C4: P06 | D4: Headphones | E4: Accessories | F4: London | G4: C034 | H4: Park Customer 34 | I4: B2C | J4: Ben Clarke | K4: 3 | L4: 55 | M4: 22 | N4: 0.05
A5: NB10004 | B5: 46043 | C5: P06 | D5: Headphones | E5: Accessories | F5: North West | G5: C024 | H5: Oak Customer 24 | I5: B2B | J5: Chloe Evans | K5: 6 | L5: 55 | M5: 22 | N5: 0.1
A6: NB10005 | B6: 46083 | C6: P01 | D6: Laptop | E6: Computers | F6: North West | G6: C019 | H6: River Customer 19 | I6: B2C | J6: Ben Clarke | K6: 2 | L6: 617.5 | M6: 430 | N6: 0
A7: NB10006 | B7: 46104 | C7: P01 | D7: Laptop | E7: Computers | F7: South East | G7: C016 | H7: Park Customer 16 | I7: B2C | J7: Ben Clarke | K7: 2 | L7: 682.5 | M7: 430 | N7: 0
A8: NB10007 | B8: 46172 | C8: P05 | D8: Mouse | E8: Accessories | F8: Midlands | G8: C009 | H8: Hill Customer 09 | I8: B2B | J8: Aisha Khan | K8: 5 | L8: 20 | M8: 7 | N8: 0
A9: NB10008 | B9: 46182 | C9: P01 | D9: Laptop | E9: Computers | F9: South East | G9: C036 | H9: Oak Customer 36 | I9: B2B | J9: Chloe Evans | K9: 7 | L9: 650 | M9: 430 | N9: 0.05
A10: NB10009 | B10: 46123 | C10: P04 | D10: Keyboard | E10: Accessories | F10: Midlands | G10: C026 | H10: Cedar Customer 26 | I10: B2C | J10: Aisha Khan | K10: 2 | L10: 35 | M10: 14 | N10: 0
A11: NB10010 | B11: 46125 | C11: P02 | D11: Monitor | E11: Computers | F11: north west | G11: C023 | H11: Maple Customer 23 | I11: B2C | J11: Aisha Khan | K11: 3 | L11: 171 | M11: 95 | N11: 0.05
A12: NB10011 | B12: 46147 | C12: P05 | D12: Mouse | E12: Accessories | F12: Midlands | G12: C033 | H12: Hill Customer 33 | I12: B2B | J12: Daniel Reed | K12: 6 | L12: 21 | M12: 7 | N12: 0.15
A13: NB10012 | B13: 46078 | C13: P01 | D13: Laptop | E13: Computers | F13: Midlands | G13: C035 | H13: Maple Customer 35 | I13: B2C | J13: Chloe Evans | K13: 2 | L13: 650 | M13: 430 | N13: 0.05
... A33: NB10032 | B33: 46037 | C33: P08 | D33: Office Chair | E33: Furniture | F33: London | G33: C029 | H33: Maple Customer 29 | I33: B2C | J33: Chloe Evans | K33: 2 | L33: 130 | M33: 65 | N33: 0.05
A34: NB10033 | B34: 46107 | C34: P08 | D34: Office Chair | F34: Midlands | G34: C027 | H34: Hill Customer 27 | I34: B2B | J34: Aisha Khan | K34: 4 | L34: 123.5 | M34: 65 | N34: 0
A35: NB10034 | B35: 46037 | C35: P04 | D35: Keyboard | E35: Accessories | F35: North West | G35: C034 | H35: Park Customer 34 | I35: B2C | J35: Daniel Reed | K35: 2 | L35: 36.75 | M35: 14 | N35: 0
A36: NB10035 | B36: 46202 | C36: P03 | D36: Tablet | E36: Computers | F36: London | G36: C025 | H36: River Customer 25 | I36: B2C | J36: Chloe Evans | K36: 4 | L36: 260 | M36: 155 | N36: 0.1
A37: NB10036 | B37: 46197 | C37: P03 | D37: Tablet | E37: Computers | F37: North West | G37: C036 | H37: Oak Customer 36 | I37: B2B | J37: Aisha Khan | K37: 7 | L37: 247 | M37: 155 | N37: 0
A38: NB10037 | B38: 46055 | C38: P03 | D38: Tablet | E38: Computers | F38: midlands | G38: C013 | H38: River Customer 13 | I38: B2C | J38: Daniel Reed | K38: 2 | L38: 260 | M38: 155 | N38: 0.15
A39: NB10038 | B39: 46060 | C39: P06 | D39: Headphones | E39: Accessories | F39: Midlands | G39: C019 | H39: River Customer 19 | I39: B2C | J39: Daniel Reed | K39: 3 | L39: 55 | M39: 22 | N39: 0.1
A40: NB10039 | B40: 46033 | C40: P02 | D40: Monitor | E40: Computers | F40: Midlands | G40: C014 | H40: Cedar Customer 14 | I40: B2C | J40: Aisha Khan | K40: 2 | L40: 180 | M40: 95 | N40: 0
A41: NB10039 | B41: 46033 | C41: P02 | D41: Monitor | E41: Computers | F41: Midlands | G41: C014 | H41: Cedar Customer 14 | I41: B2C | J41: Aisha Khan | K41: 2 | L41: 180 | M41: 95 | N41: 0
A42: NB10040 | B42: 46121 | C42: P04 | D42: Keyboard | E42: Accessories | F42: South East | G42: C025 | H42: River Customer 25 | I42: B2C | J42: Chloe Evans | K42: 3 | L42: 35 | M42: 14 | N42: 0.15
A43: NB10041 | B43: 46199 | C43: P02 | D43: Monitor | E43: Computers | F43: South East | G43: C013 | H43: River Customer 13 | I43: B2C | J43: Aisha Khan | K43: 3 | L43: 171 | M43: 95 | N43: 0.05
A44: NB10042 | B44: 46071 | C44: P06 | D44: Headphones | E44: Accessories | F44: Midlands | G44: C027 | H44: Hill Customer 27 | I44: B2B | J44: Aisha Khan | K44: 2 | L44: 52.25 | M44: 22 | N44: 0
A45: NB10043 | B45: 46115 | C45: P04 | D45: Keyboard | E45: Accessories | F45: London | G45: C003 | I45: B2B | J45: Chloe Evans | K45: 12 | L45: 36.75 | M45: 14 | N45: 0
A46: NB10044 | B46: 46179 | C46: P07 | D46: Desk | E46: Furniture | F46: North West | G46: C006 | H46: Oak Customer 06 | I46: B2B | J46: Daniel Reed | K46: 11 | L46: 170 | M46: 95 | N46: 0
A47: NB10045 | B47: 46100 | C47: P01 | D47: Laptop | E47: Computers | F47: North West | G47: C020 | H47: Cedar Customer 20 | I47: B2C | J47: Aisha Khan | K47: 4 | L47: 650 | M47: 430 | N47: 0
A48: NB10046 | B48: 46170 | C48: P04 | D48: Keyboard | E48: Accessories | F48: London | G48: C017 | H48: Maple Customer 17 | I48: B2C | J48: Daniel Reed | K48: 3 | L48: 36.75 | M48: 14 | N48: 0.15
A49: NB10047 | B49: 46133 | C49: P05 | D49: Mouse | E49: Accessories | F49: Midlands | G49: C040 | H49: Park Customer 40 | I49: B2C | J49: Chloe Evans | K49: 1 | L49: 20 | M49: 7 | N49: 0.15
A50: NB10048 | B50: 46149 | C50: P03 | D50: Tablet | E50: Computers | F50: London | G50: C006 | H50: Oak Customer 06 | I50: B2B | J50: Aisha Khan | K50: 7 | L50: 260 | M50: 155 | N50: 0
A51: NB10049 | B51: 46113 | C51: P04 | D51: Keyboard | E51: Accessories | F51: South East | G51: C012 | H51: Oak Customer 12 | I51: B2B | J51: Ben Clarke | K51: 3 | L51: 33.25 | M51: 14 | N51: 0
A52: NB10050 | B52: 46093 | C52: P01 | D52: Laptop | E52: Computers | F52: South East | G52: C005 | H52: Maple Customer 05 | I52: B2C | J52: Chloe Evans | K52: 4 | L52: 617.5 | M52: 430 | N52: 0.15
A53: NB10051 | B53: 46077 | C53: P06 | D53: Headphones | E53: Accessories | F53: North West | G53: C014 | H53: Cedar Customer 14 | I53: B2C | J53: Ben Clarke | K53: 4 | L53: 52.25 | M53: 22 | N53: 0
A54: NB10052 | B54: 46115 | C54: P08 | D54: Office Chair | E54: Furniture | F54: North West | G54: C013 | H54: River Customer 13 | I54: B2C | J54: Aisha Khan | K54: 3 | L54: 136.5 | N54: 0.05
A55: NB10053 | B55: 46093 | C55: P04 | D55: Keyboard | E55: Accessories | F55: London | G55: C018 | H55: Oak Customer 18 | I55: B2B | J55: Daniel Reed | K55: 2 | L55: 36.75 | M55: 14 | N55: 0
A56: NB10054 | B56: 46184 | C56: P01 | D56: Laptop | E56: Computers | F56: London | G56: C037 | H56: River Customer 37 | I56: B2C | J56: Daniel Reed | K56: 3 | L56: 682.5 | M56: 430 | N56: 0
A57: NB10055 | B57: 46065 | C57: P06 | D57: Headphones | E57: Accessories | F57: North West | G57: C039 | H57: Hill Customer 39 | I57: B2B | J57: Chloe Evans | K57: 5 | L57: 55 | M57: 22 | N57: 0
A58: NB10056 | B58: 46124 | C58: P01 | D58: LAPTOP | E58: Computers | F58: North West | G58: C005 | H58: Maple Customer 05 | I58: B2C | J58: Ben Clarke | K58: 2 | L58: 617.5 | M58: 430 | N58: 0.1
A59: NB10057 | B59: 46030 | C59: P07 | D59: Desk | E59: Furniture | F59: London | G59: C037 | H59: River Customer 37 | I59: B2C | J59: Chloe Evans | K59: 3 | L59: 170 | M59: 95 | N59: 0.1
...

Sheet Inspection Notes
A1: Column / area | B1: Issue observed | C1: Example order or cell | D1: Why it matters | E1: Proposed treatment / question
A2: Category | B2: 6 blank cells | C2: NB10204 | D2: Category summaries could be incomplete. | E2: Retrieve the category from Product Reference using Product ID.
A3: Customer Name | B3: 6 blank cells | C3: NB10226 | D3: Customer reports would contain missing names. | E3: Retrieve the name from Customer Reference using Customer ID.
A4: Unit Cost | B4: 5 blank cells | C4: NB10253 | D4: Product cost, gross profit and margin cannot be calculated reliably. | E4: Retrieve the unit cost from Product Reference using Product ID.
A5: Quantity | B5: 2 blank cells | C5: NB10299 | D5: Revenue and product cost cannot be calculated for these orders. | E5: Request the original transaction quantities. If unavailable, flag the orders and document their exclusion from affected calculations. Do not guess.
A6: Salesperson | B6: 2 blank cells | C6: NB10112 | D6: Sales cannot be fully attributed to individual salespeople. | E6: Request the missing names. If unavailable, label them “Unknown” and retain the sales in overall totals.
A7: Order Date | B7: 4 dates stored as text | C7: NB10240 | D7: Date sorting, calculations and monthly grouping could be unreliable. | E7: Convert them to genuine Excel dates using UK day/month/year order.
A8: Quantity | B8: 5 quantities stored as text | C8: NB10284 | D8: Numeric calculations and summaries could be unreliable. | E8: Convert to numbers and check that quantities are positive whole numbers.
A9: Unit Price | B9: 5 prices stored as text, including a £ symbol | C9: NB10282 | D9: Revenue calculations and numeric summaries could be unreliable. | E9: Remove the text currency symbol, convert to numbers and apply currency formatting.
A10: Discount Rate | B10: 4 percentages stored as text | C10: NB10259 | D10: Discount and revenue calculations could be unreliable. | E10: Convert to numeric percentages, preserving the rate—for example, 10% must equal 0.10.
A11: Product | B11: 9 names use inconsistent uppercase text | C11: NB10290: OFFICE CHAIR | D11: Product labels are inconsistent and could affect matching or reporting. | E11: Standardise names against Product Reference using Product ID.
A12: Region | B12: 13 values contain extra spaces and lowercase text | C12: NB10010 | D12: The same region could appear as separate groups or fail to match criteria. | E12: Remove leading/trailing spaces and standardise region capitalisation.
... A17: Unknown Saleperson | B17: 2 blank cells fill with "Unkonwn" | C17: NB10112, NB10232 | D17: We can not recover those information but we do not want it to attribute to the wrong person. | E17: Missing salesperson names could not be recovered. Labelled “Unknown”; orders retained in overall sales totals.
A18: removed duplicate data | B18: 5 exact duplicate records, 358 record remaning | D18: Removed because they were dupicate data.

Sheet Excluded Records
A1: Order ID | B1: Order Date | C1: Product ID | D1: Product | E1: Category | F1: Region | G1: Customer ID | H1: Customer Name | I1: Customer Type | J1: Salesperson | K1: Quantity | L1: Unit Price | M1: Unit Cost | N1: Discount Rate
A2: NB10146 | B2: 46025 | C2: P07 | D2: Desk | E2: Furniture | F2: London | G2: C021 | H2: Hill Customer 21 | I2: B2B | J2: Ben Clarke | L2: 170 | M2: 95 | N2: 0
A3: NB10299 | B3: 46187 | C3: P08 | D3: Office Chair | E3: Furniture | F3: North West | G3: C026 | H3: Cedar Customer 26 | I3: B2C | J3: Chloe Evans | L3: 136.5 | M3: 65 | N3: 0.15
